<?xml version="1.0"?> 
<robot name="glide" xmlns:xacro="http://www.ros.org/wiki/xacro">
  <material name="blue">
    <color rgba="0 0 0.8 1"/>
  </material>

  <material name="white">
    <color rgba="1 1 1 1"/>
  </material>

  <xacro:property name="body_width" value="0.2" /> <!-- 8" ~= 0.2 m -->
  <xacro:property name="body_length" value="0.3" /> <!-- 12" ~= 0.3 m -->
  <xacro:property name="body_height" value="0.1" /> <!-- 4" ~= 0.1 m -->
  <xacro:property name="body_center" value="0.1" /> <!-- 4" ~= 0.1 m -->

  <xacro:property name="wheel_width" value="0.003" /> <!-- 1/8" ~= 0.003 m -->
  <xacro:property name="wheel_radius" value="0.077" /> <!-- 3 1/16" ~= 0.077 m -->
  <xacro:property name="wheel_gap" value="0.03175" /> <!-- 1 1/4" ~= 0.03175 m -->
  <xacro:property name="wheel_offset" value="0.0381" /> <!-- 1 5" ~= 0.0381 m -->

  <xacro:property name="degrees_45" value="${45 * pi/180}"/>
  <xacro:property name="degrees_90" value="${90 * pi/180}"/>

  <xacro:macro name="steer_wheel" params="name xy_reflect">
    <link name="${name}_steer_wheel">
      <visual>
        <geometry>
          <cylinder length="${wheel_width}" radius="${wheel_radius}"/>
        </geometry>
        <origin rpy="${degrees_90} 0 0" xyz="${wheel_offset} ${xy_reflect * (wheel_gap + body_width/2)} ${wheel_radius}"/>
        <material name="white"/>
      </visual>
      <collision> 
        <origin rpy="${degrees_90} 0 0" xyz="${wheel_offset} ${xy_reflect * (wheel_gap + body_width/2)} ${wheel_radius}"/>
        <geometry> 
          <cylinder length="${wheel_width}" radius="${wheel_radius}"/>
        </geometry> 
      </collision>
      <inertial> 
        <origin rpy="${degrees_90} 0 0" xyz="${wheel_offset} ${xy_reflect * (wheel_gap + body_width/2)} ${wheel_radius}"/>
        <!-- <mass value="0.2"/>  -->
        <!--<cylinder_inertia m="0.2" r="0.3" h="0.1"/> -->
        <!-- <cylinder_inirtia m="${mass}" r="${radius}" h="${width}" /> -->
        <!--<inertia ixx="0.23" ixy="0" ixz="0" iyy="0.23" iyz="0" izz="0.4"/>-->
	    </inertial> 
    </link>

    <joint name="base_to_${name}_steer_wheel" type="continuous">
      <parent link="base_link"/>
      <child link="${name}_steer_wheel"/>
      <axis xyz="0 1 0"/>
    </joint>
  </xacro:macro>


  <link name="base_link">
    <visual>
      <geometry>
        <box size="${body_length} ${body_width} ${body_height}"/>
      </geometry>
      <origin rpy="0 0 0" xyz="0 0 ${body_center}"/>
      <material name="blue"/>
    </visual>
  </link>

  <xacro:steer_wheel name="right" xy_reflect="-1" />
  <xacro:steer_wheel name="left" xy_reflect="1" />


  <!-- <link name="human_link">
    <visual>
      <geometry>
        <box size="${body_length} ${body_width} ${body_height}"/>
      </geometry>
      <material name="blue"/>
    </visual>
  </link> -->

</robot> 