<?xml version="1.0" ?>
<sdf version="1.5">
      <model name="glide_bot">
        <link name="base_link">
            <pose>0 0 0.1 0 0 0</pose>
            <collision name="base_collision">
                <geometry>
                    <box>
                        <size>0.3 0.2 0.1</size>
                    </box>
                </geometry>
            </collision>

            <visual name="base_visual">
                <geometry>
                    <box>
                        <size>0.3 0.2 0.1</size>
                    </box>
                </geometry>
                <material>
                    <ambient>0.0 0.0 0.0 1.0</ambient>
                    <diffuse>0.0 0.0 0.0 1.0</diffuse>
                    <specular>0.0 0.0 0.0 1.0</specular>
                    <emissive>0.0 0.0 0.0 1.0</emissive>
                </material>
            </visual>
        </link>

        <link name="front_left_wheel">
            <pose>-0.061900000000000004 0.13175 0.08 1.5707963267948966 0 3.14159265359</pose>
            <visual name ="front_left_wheel_visual">
                <geometry>
                    <cylinder> 
                        <length>0.003</length> 
                        <radius>0.077</radius>
                    </cylinder>
                </geometry>
            </visual>

            <inertial>
                <mass>5</mass>
                <inertia> 
                    <ixx>7.90866056</ixx> 
                    <ixy>0.00000006</ixy>
                    <ixz>0.0</ixz>
                    <iyy>7.90866056</iyy>
                    <iyz>0.0</iyz>
                    <izz>2.48398783</izz>
                </inertia>
            </inertial>

            <collision name ="front_left_wheel_collision">
                <geometry>
                    <cylinder> 
                        <length>0.003</length> 
                        <radius>0.077</radius>
                    </cylinder>
                </geometry>
            </collision>
        </link>

        <link name="front_right_wheel">
            <pose>-0.061900000000000004 -0.13175 0.08 1.5707963267948966 0 3.14159265359</pose>
            <visual name ="front_right_wheel_visual">
                <geometry>
                    <cylinder>
                        <radius>0.077</radius>
                        <length>0.003</length>
                    </cylinder>
                </geometry>
            </visual>

            <inertial>
                <mass>5</mass>
                <inertia> 
                    <ixx>7.90866056</ixx> 
                    <ixy>0.00000006</ixy>
                    <ixz>0.0</ixz>
                    <iyy>7.90866056</iyy>
                    <iyz>0.0</iyz>
                    <izz>2.48398783</izz>
                </inertia>
            </inertial>

            <collision name="front_right_wheel_collision">
                <geometry>
                    <cylinder>
                        <radius>0.077</radius>
                        <length>0.003</length>
                    </cylinder>
                </geometry>
            </collision>
        </link>


      <link name="rear_left_wheel">
        <pose>-1.0 0.13175 0.08 1.5707963267948966 0 3.14159265359</pose>
            <visual name ="rear_left_wheel_visual">
                <geometry>
                    <cylinder> 
                        <length>0.003</length> 
                        <radius>0.077</radius>
                    </cylinder>
                </geometry>
            </visual>

            <inertial>
                <mass>5</mass>
                <inertia> 
                    <ixx>7.90866056</ixx> 
                    <ixy>0.00000006</ixy>
                    <ixz>0.0</ixz>
                    <iyy>7.90866056</iyy>
                    <iyz>0.0</iyz>
                    <izz>2.48398783</izz>
                </inertia>
            </inertial>

            <collision name ="rear_left_wheel_collision">
                <geometry>
                    <cylinder> 
                        <length>0.003</length> 
                        <radius>0.077</radius>
                    </cylinder>
                </geometry>
            </collision>
      </link>

      <link name="rear_right_wheel">
        <pose>-1.0 -0.13175 0.08 1.5707963267948966 0 3.14159265359</pose>
            <visual name ="rear_right_steer_wheel_visual">
                <geometry>
                    <cylinder>
                        <radius>0.077</radius>
                        <length>0.003</length>
                    </cylinder>
                </geometry>
            </visual>

            <inertial>
                <mass>5</mass>
                <inertia> 
                    <ixx>7.90866056</ixx> 
                    <ixy>0.00000006</ixy>
                    <ixz>0.0</ixz>
                    <iyy>7.90866056</iyy>
                    <iyz>0.0</iyz>
                    <izz>2.48398783</izz>
                </inertia>
            </inertial>

            <collision name="rear_right_steer_wheel_collision">
                <geometry>
                    <cylinder>
                        <radius>0.077</radius>
                        <length>0.003</length>
                    </cylinder>
                </geometry>
            </collision>
      </link>

      <joint type="universal" name="front_left_wheel_joint">
        <pose>0 0 0 0 0 0</pose>
        <child>front_left_wheel</child>
        <parent>base_link</parent>
        <axis>
            <xyz>0 1 0</xyz>
            <limit>
                <lower>-0.9</lower>
                <upper>0.9</upper>
            </limit>
        </axis>
        <axis2>
            <xyz>0 0 1</xyz>
        </axis2>
      </joint>

      <joint type="universal" name="front_right_wheel_joint">
        <pose>0 0 0 0 0 0</pose>
        <child>front_right_wheel</child>
        <parent>base_link</parent>
        <axis>
            <xyz>0 1 0</xyz>
            <limit>
                <lower>-0.9</lower>
                <upper>0.9</upper>
            </limit>
        </axis>
        <axis2>
          <xyz>0 0 1</xyz>
        </axis2>
      </joint>

      <joint type="revolute" name="rear_left_wheel_joint">
          <child>rear_left_wheel</child>
          <parent>base_link</parent>
          <axis>
              <xyz>0 0 1</xyz>
          </axis>
      </joint>
      <joint type="revolute" name="rear_right_wheel_joint">
          <child>rear_right_wheel</child>
          <parent>base_link</parent>
          <axis>
              <xyz>0 0 1</xyz>
          </axis>
      </joint>

      <link name="human_link">
          <pose>-1.0 0.0 0.154 0 1.5707963267948966 0</pose>
          <visual name ="human_visual">
              <geometry>
                  <box>
                      <size>0.3 0.2 0.1</size>
                  </box>
              </geometry>
          </visual>

          <collision name="human_collision">
              <geometry>
                  <box>
                      <size>0.3 0.2 0.1</size>
                  </box>
              </geometry>
          </collision>
      </link>
      <joint name="base_to_human" type="fixed">
          <pose>0 0 0 0 0 0</pose>
          <parent>base_link</parent>
          <child>human_link</child>
      </joint>

    <link name="realsense_link">
      <pose>0.4 0 0.25 0 0 0</pose>
      <visual name="realsense_link_visual">
        <pose>0 0 0 0 0 -1.57</pose>
        <geometry>
          <box>
            <size>0.02505 0.090 0.025</size>
          </box>
        </geometry>
      </visual>
      <collision name="realsense_link_collision">
        <pose>0 0 0 -1.57 0 -1.57</pose>
        <geometry>
          <box>
            <size>0.02505 0.090 0.025</size>
          </box>
        </geometry>
      </collision>
      <inertial>
        <pose>0 0 0 0 0 0</pose>
        <inertia>
          <ixx>0.001</ixx>
          <ixy>0.000</ixy>
          <ixz>0.000</ixz>
          <iyy>0.001</iyy>
          <iyz>0.000</iyz>
          <izz>0.001</izz>
        </inertia>
        <mass>0.564</mass>
      </inertial>

      <sensor name="cameradepth" type="depth">
        <camera name="camera">
          <horizontal_fov>1.57</horizontal_fov>
          <image>
            <width>1280</width>
            <height>720</height>
          </image>
          <clip>
            <near>0.1</near>
            <far>100</far>
          </clip>
          <noise>
            <type>gaussian</type>
            <mean>0.0</mean>
            <stddev>0.100</stddev>
          </noise>
        </camera>
        <always_on>1</always_on>
        <update_rate>30</update_rate>
        <visualize>0</visualize>
      </sensor>
      <sensor name="cameracolor" type="camera">
        <camera name="camera">
          <horizontal_fov>1.57</horizontal_fov>
          <image>
            <width>1280</width>
            <height>720</height>
            <format>RGB_INT8</format>
          </image>
          <clip>
            <near>0.1</near>
            <far>100</far>
          </clip>
          <noise>
            <type>gaussian</type>
            <mean>0.0</mean>
            <stddev>0.007</stddev>
          </noise>
        </camera>
        <always_on>1</always_on>
        <update_rate>30</update_rate>
        <visualize>1</visualize>
      </sensor>
      <sensor name="cameraired1" type="camera">
        <camera name="camera">
          <horizontal_fov>1.57</horizontal_fov>
          <image>
            <width>1280</width>
            <height>720</height>
            <format>L_INT8</format>
          </image>
          <clip>
            <near>0.1</near>
            <far>100</far>
          </clip>
          <noise>
            <type>gaussian</type>
            <mean>0.0</mean>
            <stddev>0.05</stddev>
          </noise>
        </camera>
        <always_on>1</always_on>
        <update_rate>1</update_rate>
        <visualize>0</visualize>
      </sensor>
      <sensor name="cameraired2" type="camera">
        <camera name="camera">
          <horizontal_fov>1.57</horizontal_fov>
          <image>
            <width>1280</width>
            <height>720</height>
            <format>L_INT8</format>
          </image>
          <clip>
            <near>0.1</near>
            <far>100</far>
          </clip>
          <noise>
            <type>gaussian</type>
            <mean>0.0</mean>
            <stddev>0.05</stddev>
          </noise>
        </camera>
        <always_on>1</always_on>
        <update_rate>1</update_rate>
        <visualize>0</visualize>
      </sensor>
    </link>

    <joint name="realsense_joint" type="fixed">
      <parent>base_link</parent>
      <child>realsense_link</child>
      <pose>0.4 0 0.4 0 0 0</pose>
    </joint>

    <plugin name="camera" filename="librealsense_gazebo_plugin.so">
      <prefix>camera</prefix>
      <depthUpdateRate>30.0</depthUpdateRate>
      <colorUpdateRate>30.0</colorUpdateRate>
      <infraredUpdateRate>1.0</infraredUpdateRate>
      <depthTopicName>depth/image_rect_raw</depthTopicName>
      <depthCameraInfoTopicName>depth/camera_info</depthCameraInfoTopicName>
      <colorTopicName>color/image_raw</colorTopicName>
      <colorCameraInfoTopicName>color/camera_info</colorCameraInfoTopicName>
      <infrared1TopicName>infra1/image_raw</infrared1TopicName>
      <infrared1CameraInfoTopicName>infra1/camera_info</infrared1CameraInfoTopicName>
      <infrared2TopicName>infra2/image_raw</infrared2TopicName>
      <infrared2CameraInfoTopicName>infra2/camera_info</infrared2CameraInfoTopicName>
      <colorOpticalframeName>camera_color_optical_frame</colorOpticalframeName>
      <depthOpticalframeName>camera_depth_optical_frame</depthOpticalframeName>
      <infrared1OpticalframeName>camera_left_ir_optical_frame</infrared1OpticalframeName>
      <infrared2OpticalframeName>camera_right_ir_optical_frame</infrared2OpticalframeName>
      <rangeMinDepth>0.3</rangeMinDepth>
      <rangeMaxDepth>3.0</rangeMaxDepth>
      <pointCloud>true</pointCloud>
      <pointCloudTopicName>depth/color/points</pointCloudTopicName>
      <pointCloudCutoff>0.3</pointCloudCutoff>
    </plugin>

      <plugin name='ackermann_drive' filename='libgazebo_ros_ackermann_drive.so'>

        <update_rate>10.0</update_rate>

        <!-- wheels -->
        <front_left_joint>front_left_wheel_joint</front_left_joint>
        <front_right_joint>front_right_wheel_joint</front_right_joint>
        <rear_left_joint>rear_left_wheel_joint</rear_left_joint>
        <rear_right_joint>rear_right_wheel_joint</rear_right_joint>
        <left_steering_joint>front_left_wheel_joint</left_steering_joint>
        <right_steering_joint>front_right_wheel_joint</right_steering_joint>

        <!-- Max absolute steer angle for tyre in radians-->
        <!-- Any cmd_vel angular z greater than this would be capped -->
        <max_steer>0.2</max_steer>

        <!-- Max absolute steering angle of steering wheel -->
        <max_steering_angle>7.85</max_steering_angle>

        <!-- Max absolute linear speed in m/s -->
        <max_speed>1</max_speed>

        <!-- PID tuning -->
        <left_steering_pid_gain>1500 0 1</left_steering_pid_gain>
        <left_steering_i_range>0 0</left_steering_i_range>
        <right_steering_pid_gain>1500 0 1</right_steering_pid_gain>
        <right_steering_i_range>0 0</right_steering_i_range>
        <linear_velocity_pid_gain>1000 0 1</linear_velocity_pid_gain>
        <linear_velocity_i_range>0 0</linear_velocity_i_range>

        <!-- output -->
        <publish_odom>true</publish_odom>
        <publish_odom_tf>true</publish_odom_tf>
        <publish_wheel_tf>true</publish_wheel_tf>
        <publish_distance>true</publish_distance>

        <odometry_topic>odom</odometry_topic>
        <odometry_frame>odom</odometry_frame>
        <robot_base_frame>base_link</robot_base_frame>

        <ros>
          <remapping>odom:=wheel/odometry</remapping>
        </ros>

      </plugin>
    </model>
<!--     <model name="glide_bot">  
    <static>true</static>

        <link name="base_link">
            <pose>0 0 0.1 0 0 0</pose>
            <collision name="base_collision">
                <geometry>
                    <box>
                        <size>0.3 0.2 0.1</size>
                    </box>
                </geometry>
            </collision>

            <visual name="base_visual">
                <geometry>
                    <box>
                        <size>0.3 0.2 0.1</size>
                    </box>
                </geometry>
                <material>
                    <ambient>0.0 0.0 0.0 1.0</ambient>
                    <diffuse>0.0 0.0 0.0 1.0</diffuse>
                    <specular>0.0 0.0 0.0 1.0</specular>
                    <emissive>0.0 0.0 0.0 1.0</emissive>
                </material>
            </visual>
        </link>

        <link name="front_right_steer_wheel_link">
            <pose>-0.061900000000000004 -0.13175 0.077 1.5707963267948966 0 0</pose>
            <visual name ="front_right_steer_wheel_visual">
                <geometry>
                    <cylinder>
                        <radius>0.077</radius>
                        <length>0.003</length>
                    </cylinder>
                </geometry>
            </visual>

            <inertial>
                <mass>5</mass>
                <inertia> 
                    <ixx>0.23</ixx> 
                    <ixy>0.0</ixy>
                    <ixz>0.0</ixz>
                    <iyy>0.23</iyy>
                    <iyz>0.0</iyz>
                    <izz>0.4</izz>
                </inertia>
            </inertial>

            <collision name="front_right_steer_wheel_collision">
                <geometry>
                    <cylinder>
                        <radius>0.077</radius>
                        <length>0.003</length>
                    </cylinder>
                </geometry>
            </collision>
        </link>

        <joint name="base_to_front_right_steer_wheel" type="universal">
            <pose>0 0 0 0 0 0</pose>
            <parent>base_link</parent>
            <child>front_right_steer_wheel_link</child>
            <axis>
                <xyz>0 1 0</xyz>
                <limit>
                    <lower>-0.2</lower>
                    <upper>0.2</upper>
                </limit>
            </axis>
            <axis2>
                <xyz>0 0 1</xyz>
            </axis2>
        </joint>

        <link name="front_right_rotate_wheel_link">
            <pose>-0.061900000000000004 -0.13175 0.077 1.5707963267948966 0 0</pose>
            <visual name ="front_right_rotate_wheel_visual">
                <geometry>
                    <cylinder>
                        <radius>0.001</radius>
                        <length>0.001</length>
                    </cylinder>
                </geometry>
            </visual>

            <inertial>
                <mass>5</mass>
                <inertia> 
                    <ixx>0.23</ixx> 
                    <ixy>0.0</ixy>
                    <ixz>0.0</ixz>
                    <iyy>0.23</iyy>
                    <iyz>0.0</iyz>
                    <izz>0.4</izz>
                </inertia>
            </inertial>

            <collision name="front_right_rotate_wheel_collision">
                <geometry>
                    <cylinder>
                        <radius>0.001</radius>
                        <length>0.001</length>
                    </cylinder>
                </geometry>
            </collision>
        </link>

        <joint name="front_right_steer_to_front_right_rotate_wheel" type="revolute">
            <pose>0 0 0 0 0 0</pose>
            <parent>front_right_steer_wheel_link</parent>
            <child>front_right_rotate_wheel_link</child>
            <axis>
                <xyz>0 0 1</xyz>
            </axis>
        </joint>

        <link name="front_left_steer_wheel_link">
            <pose>-0.061900000000000004 0.13175 0.077 1.5707963267948966 0 0</pose>
            <visual name ="front_left_steer_wheel_visual">
                <geometry>
                    <cylinder> 
                        <length>0.003</length> 
                        <radius>0.077</radius>
                    </cylinder>
                </geometry>
            </visual>

            <inertial>
                <mass>5</mass>
                <inertia> 
                    <ixx>0.23</ixx> 
                    <ixy>0.0</ixy>
                    <ixz>0.0</ixz>
                    <iyy>0.23</iyy>
                    <iyz>0.0</iyz>
                    <izz>0.4</izz>
                </inertia>
            </inertial>

            <collision name ="front_left_steer_wheel_collision">
                <geometry>
                    <cylinder> 
                        <length>0.003</length> 
                        <radius>0.077</radius>
                    </cylinder>
                </geometry>
            </collision>
        </link>

        <joint name="base_to_front_left_steer_wheel" type="universal">
            <pose>0 0 0 0 0 0</pose>
            <parent>base_link</parent>
            <child>front_left_steer_wheel_link</child>
            <axis>
                <xyz>0 1 0</xyz>
                <limit>
                    <lower>-0.2</lower>
                    <upper>0.2</upper>
                </limit>
            </axis>
            <axis2>
                <xyz>0 0 1</xyz>
            </axis2>
        </joint>

        <link name="front_left_rotate_wheel_link">
            <pose>-0.061900000000000004 0.13175 0.077 1.5707963267948966 0 0</pose>
            <visual name ="front_left_rotate_wheel_visual">
                <geometry>
                    <cylinder>
                        <radius>0.001</radius>
                        <length>0.001</length>
                    </cylinder>
                </geometry>
            </visual>

            <inertial>
                <mass>5</mass>
                <inertia> 
                    <ixx>0.23</ixx> 
                    <ixy>0.0</ixy>
                    <ixz>0.0</ixz>
                    <iyy>0.23</iyy>
                    <iyz>0.0</iyz>
                    <izz>0.4</izz>
                </inertia>
            </inertial>

            <collision name="front_left_rotate_wheel_collision">
                <geometry>
                    <cylinder>
                        <radius>0.001</radius>
                        <length>0.001</length>
                    </cylinder>
                </geometry>
            </collision>
        </link>

        <joint name="front_left_steer_to_front_left_rotate_wheel" type="revolute">
            <pose>0 0 0 0 0 0</pose>
            <parent>front_left_steer_wheel_link</parent>
            <child>front_left_rotate_wheel_link</child>
            <axis>
                <xyz>0 0 1</xyz>
            </axis>
        </joint>

        <link name="rear_right_steer_wheel_link">
            <pose>-0.5119 -0.13175 0.077 1.5707963267948966 0 0</pose>
            <visual name ="rear_right_steer_wheel_visual">
                <geometry>
                    <cylinder>
                        <radius>0.077</radius>
                        <length>0.003</length>
                    </cylinder>
                </geometry>
            </visual>

            <inertial>
                <mass>5</mass>
                <inertia> 
                    <ixx>0.23</ixx> 
                    <ixy>0.0</ixy>
                    <ixz>0.0</ixz>
                    <iyy>0.23</iyy>
                    <iyz>0.0</iyz>
                    <izz>0.4</izz>
                </inertia>
            </inertial>

            <collision name="rear_right_steer_wheel_collision">
                <geometry>
                    <cylinder>
                        <radius>0.077</radius>
                        <length>0.003</length>
                    </cylinder>
                </geometry>
            </collision>
        </link>

        <joint name="base_to_rear_right_steer_wheel" type="revolute">
            <pose>0 0 0 0 0 0</pose>
            <parent>base_link</parent>
            <child>rear_right_steer_wheel_link</child>
            <axis>
                <xyz>0 1 0</xyz>
                <limit>
                    <lower>-0.2</lower>
                    <upper>0.2</upper>
                </limit>
            </axis>
        </joint>

        <link name="rear_right_rotate_wheel_link">
            <pose>-0.5119 -0.13175 0.077 1.5707963267948966 0 0</pose>
            <visual name ="rear_right_rotate_wheel_visual">
                <geometry>
                    <cylinder>
                        <radius>0.001</radius>
                        <length>0.001</length>
                    </cylinder>
                </geometry>
            </visual>

            <inertial>
                <mass>5</mass>
                <inertia> 
                    <ixx>0.23</ixx> 
                    <ixy>0.0</ixy>
                    <ixz>0.0</ixz>
                    <iyy>0.23</iyy>
                    <iyz>0.0</iyz>
                    <izz>0.4</izz>
                </inertia>
            </inertial>

            <collision name="rear_right_rotate_wheel_collision">
                <geometry>
                    <cylinder>
                        <radius>0.001</radius>
                        <length>0.001</length>
                    </cylinder>
                </geometry>
            </collision>
        </link>

        <joint name="rear_right_steer_to_rear_right_rotate_wheel" type="revolute">
            <pose>0 0 0 0 0 0</pose>
            <parent>rear_right_steer_wheel_link</parent>
            <child>rear_right_rotate_wheel_link</child>
            <axis>
                <xyz>0 0 1</xyz>
            </axis>
        </joint>

        <link name="rear_left_steer_wheel_link">
            <pose>-0.5119 0.13175 0.077 1.5707963267948966 0 0</pose>
            <visual name ="rear_left_steer_wheel_visual">
                <geometry>
                    <cylinder> 
                        <length>0.003</length> 
                        <radius>0.077</radius>
                    </cylinder>
                </geometry>
            </visual>

            <inertial>
                <mass>5</mass>
                <inertia> 
                    <ixx>0.23</ixx> 
                    <ixy>0.0</ixy>
                    <ixz>0.0</ixz>
                    <iyy>0.23</iyy>
                    <iyz>0.0</iyz>
                    <izz>0.4</izz>
                </inertia>
            </inertial>

            <collision name ="rear_left_steer_wheel_collision">
                <geometry>
                    <cylinder> 
                        <length>0.003</length> 
                        <radius>0.077</radius>
                    </cylinder>
                </geometry>
            </collision>
        </link>

        <joint name="base_to_rear_left_steer_wheel" type="revolute">
            <pose>0 0 0 0 0 0</pose>
            <parent>base_link</parent>
            <child>rear_left_steer_wheel_link</child>
            <axis>
                <xyz>0 1 0</xyz>
                <limit>
                    <lower>-0.2</lower>
                    <upper>0.2</upper>
                </limit>
            </axis>
        </joint>

        <link name="rear_left_rotate_wheel_link">
            <pose>-0.5119 0.13175 0.077 1.5707963267948966 0 0</pose>
            <visual name ="rear_left_rotate_wheel_visual">
                <geometry>
                    <cylinder>
                        <radius>0.001</radius>
                        <length>0.001</length>
                    </cylinder>
                </geometry>
            </visual>

            <inertial>
                <mass>5</mass>
                <inertia> 
                    <ixx>0.23</ixx> 
                    <ixy>0.0</ixy>
                    <ixz>0.0</ixz>
                    <iyy>0.23</iyy>
                    <iyz>0.0</iyz>
                    <izz>0.4</izz>
                </inertia>
            </inertial>

            <collision name="rear_left_rotate_wheel_collision">
                <geometry>
                    <cylinder>
                        <radius>0.001</radius>
                        <length>0.001</length>
                    </cylinder>
                </geometry>
            </collision>
        </link>

        <joint name="rear_left_steer_to_rear_left_rotate_wheel" type="revolute">
            <pose>0 0 0 0 0 0</pose>
            <parent>rear_left_steer_wheel_link</parent>
            <child>rear_left_rotate_wheel_link</child>
            <axis>
                <xyz>0 0 1</xyz>
            </axis>
        </joint>

        <link name="human_link">
            <pose>-0.5 0.0 0.154 0 1.5707963267948966 0</pose>
            <visual name ="human_visual">
                <geometry>
                    <box>
                        <size>0.3 0.2 0.1</size>
                    </box>
                </geometry>
            </visual>

            <collision name="human_collision">
                <geometry>
                    <box>
                        <size>0.3 0.2 0.1</size>
                    </box>
                </geometry>
            </collision>
        </link>

        <joint name="base_to_human" type="fixed">
            <pose>0 0 0 0 0 0</pose>
            <parent>base_link</parent>
            <child>human_link</child>
        </joint>

        <link name="steer_bar_link">
            <pose>-0.36000000000000004 0 0.2727272727272727 0 0 0</pose>
            <visual name ="steer_bar_visual">
                <geometry>
                    <cylinder>
                        <length>0.4</length>
                        <radius>0.003</radius>
                    </cylinder>
                </geometry>
            </visual>

            <collision name="steer_bar_collision">
                <geometry>
                    <cylinder>
                        <length>0.4</length>
                        <radius>0.003</radius>
                    </cylinder>
                </geometry>
            </collision>
        </link>

        <joint name="base_to_steer_bar" type="revolute">
            <pose>0 0 0 0 0 0</pose>
            <parent>base_link</parent>
            <child>steer_bar_link</child>
            <axis>0 1 0</axis>
        </joint>

        <plugin name="camera" filename="librealsense_gazebo_plugin.so">
            <link name="camera_link">
                <pose>0.0043 -0.0175 0 1.5707963267948966 0 1.5707963267948966</pose>
                <visual>
                    <geometry>
                        <mesh>
                            <scale>1 1 1</scale>
                            <uri>model://realsense2_description/meshes/d435.dae</uri>
                        </mesh>
                    </geometry>
                </visual>
                <collision>
                    <geometry>
                        <box>
                            <size>0.02505 0.09 0.025</size>
                        </box>
                    </geometry>
                </collision>
                <inertial>
                    <mass>0.072</mass>
                    <inertia> 
                        <ixx>0.003881243</ixx> 
                        <ixy>0.0</ixy>
                        <ixz>0.0</ixz>
                        <iyy>0.000498940</iyy>
                        <iyz>0.0</iyz>
                        <izz>0.003879257</izz>
                    </inertia>
                </inertial>
            </link>

            <link name="camera_bottom_screw_frame">
              <pose>0 0 0 0.4 0 0.25</pose>
            </link>

            <link name="camera_depth_frame">
                <pose>0 0 0 0 0 0</pose>
            </link>

            <joint name="camera_joint" type="fixed">
              <parent>base_link</parent>
              <child>camera_bottom_screw_frame</child>
              <pose>0 0 0 0 0 0</pose>
            </joint>

            <joint name="camera_link_joint" type="fixed">
              <parent>camera_bottom_screw_frame</parent>
              <child>camera_link</child>
              <pose>0 0 0 0.010600000000000002 0.0175 0.0125</pose>
            </joint>

            <joint name="camera_depth_joint" type="fixed">
              <parent>camera_link</parent>
              <child>camera_depth_frame</child>
              <pose>0 0 0 0 0 0</pose>
            </joint>


        </plugin>

        <plugin name='glide_bot_ackermann_drive' filename='libgazebo_ros_ackermann_drive.so'>

            <ros>
              <namespace>demo</namespace>
              <remapping>cmd_vel:=cmd_demo</remapping>
              <remapping>odom:=odom_demo</remapping>
              <remapping>distance:=distance_demo</remapping>
            </ros>

            <update_rate>100.0</update_rate>

            <front_left_joint>base_to_front_left_steer_wheel</front_left_joint>
            <front_right_joint>base_to_front_right_steer_wheel</front_right_joint>
            <left_steering_joint>base_to_front_left_steer_wheel</left_steering_joint>
            <right_steering_joint>base_to_front_right_steer_wheel</right_steering_joint>
            <rear_left_joint>base_to_rear_left_steer_wheel</rear_left_joint>
            <rear_right_joint>base_to_rear_left_steer_wheel</rear_right_joint>
            <steering_wheel_joint>base_to_steer_bar</steering_wheel_joint>

            <max_steer>0.6458</max_steer>

            <max_steering_angle>7.85</max_steering_angle>

            <max_speed>20</max_speed>

            <left_steering_pid_gain>1500 0 1</left_steering_pid_gain>
            <left_steering_i_range>0 0</left_steering_i_range>
            <right_steering_pid_gain>1500 0 1</right_steering_pid_gain>
            <right_steering_i_range>0 0</right_steering_i_range>
            <linear_velocity_pid_gain>1000 0 1</linear_velocity_pid_gain>
            <linear_velocity_i_range>0 0</linear_velocity_i_range>

            <publish_odom>true</publish_odom>
            <publish_odom_tf>true</publish_odom_tf>
            <publish_wheel_tf>true</publish_wheel_tf>
            <publish_distance>true</publish_distance>

            <odometry_frame>odom_demo</odometry_frame>
            <robot_base_frame>base_link</robot_base_frame>

        </plugin>

        <plugin name="glide_bot_joint_state" filename="libgazebo_ros_joint_state_publisher.so">
            <ros>
                <remapping>~/out:=joint_states</remapping>
            </ros>
            <update_rate>30</update_rate>            
            <joint_name>front_right_steer_to_front_right_rotate_wheel</joint_name>
            <joint_name>front_left_steer_to_front_left_rotate_wheel</joint_name>
            <joint_name>rear_left_steer_to_rear_left_rotate_wheel</joint_name>
            <joint_name>rear_right_steer_to_rear_right_rotate_wheel</joint_name>
            <joint_name>base_to_front_right_steer_wheel</joint_name>
            <joint_name>base_to_rear_left_steer_wheel</joint_name>
            <joint_name>base_to_rear_right_steer_wheel</joint_name>
            <joint_name>base_to_steer_bar</joint_name>
        </plugin>   
    </model> -->
</sdf>
