<?xml version="1.0" ?>
<!-- =================================================================================== -->
<!-- |    This document was autogenerated by xacro from sim_glide_description.urdf.xacro | -->
<!-- |    EDITING THIS FILE BY HAND IS NOT RECOMMENDED                                 | -->
<!-- =================================================================================== -->
<robot name="glide">
  <material name="blue">
    <color rgba="0 0 0.8 1"/>
  </material>
  <material name="white">
    <color rgba="1 1 1 1"/>
  </material>
  <!-- 4" ~= 0.1 m -->
  <!-- 1 5" ~= 0.0381 m -->
  <!-- 1 1/4" ~= 0.03175 m -->
  <!-- <link name="steer_bar_link">
      <visual>
        <geometry>
          <cylinder length="0.4" radius="${bar_radius}"/>
        </geometry>
        <origin rpy="${degrees_45} -${degrees_45} -${degrees_55}" xyz="0 0 0"/>
        <material name="white"/>
      </visual>
      <collision> 
        <origin rpy="${degrees_45} 0 0" xyz="0 0 0"/>
        <geometry> 
          <cylinder length="0.4" radius="${bar_radius}"/>
        </geometry> 
      </collision>
  </link>
  <joint name="steer_bar_joint" type="revolute">
    <limit lower="-0.2" upper="0.2" effort="100" velocity="0.1"/>
      <origin rpy="0 0 0" xyz="-${1.8*body_width} 0 ${body_length/1.1}"/>
      <parent link="base_link"/>
      <child link="steer_bar_link"/>
      <axis xyz="0 1 0"/>
    </joint> -->
  <link name="base_link">
    <visual>
      <geometry>
        <box size="0.3 0.2 0.1"/>
      </geometry>
      <origin rpy="0 0 0" xyz="0 0 0.1"/>
      <material name="blue"/>
    </visual>
  </link>
  <gazebo reference="base_link">
    <material>Gazebo/Blue</material>
  </gazebo>
  <link name="front_right_wheel">
    <visual>
      <geometry>
        <cylinder length="0.003" radius="0.077"/>
      </geometry>
      <origin rpy="0 0 0" xyz="0 0 0"/>
      <material name="white"/>
    </visual>
    <collision>
      <origin rpy="0 0 0" xyz="0 0 0"/>
      <geometry>
        <cylinder length="0.003" radius="0.077"/>
      </geometry>
    </collision>
    <inertial>
      <origin rpy="0 0 0" xyz="0 0 0"/>
      <mass value="5.0"/>
      <!--<cylinder_inertia m="0.2" r="0.3" h="0.1"/> -->
      <!-- <cylinder_inirtia m="${mass}" r="${radius}" h="${width}" /> -->
      <inertia ixx="7.90866056" ixy="0.00000006" ixz="0" iyy="7.90866056" iyz="0" izz="2.48398783"/>
    </inertial>
  </link>
  <gazebo reference="$front_{name}_wheel">
    <material>Gazebo/White</material>
  </gazebo>
  <joint name="front_right_wheel_joint" type="revolute">
    <limit effort="100" lower="-0.9" upper="0.9" velocity="1"/>
    <origin rpy="1.5707963267948966 0 3.141592653589793" xyz="-0.061900000000000004 -0.13175 0.077"/>
    <parent link="base_link"/>
    <child link="front_right_wheel"/>
    <axis xyz="0 1 0"/>
    <axis2 xyz="0 0 1"/>
  </joint>
  <link name="front_left_wheel">
    <visual>
      <geometry>
        <cylinder length="0.003" radius="0.077"/>
      </geometry>
      <origin rpy="0 0 0" xyz="0 0 0"/>
      <material name="white"/>
    </visual>
    <collision>
      <origin rpy="0 0 0" xyz="0 0 0"/>
      <geometry>
        <cylinder length="0.003" radius="0.077"/>
      </geometry>
    </collision>
    <inertial>
      <origin rpy="0 0 0" xyz="0 0 0"/>
      <mass value="5.0"/>
      <!--<cylinder_inertia m="0.2" r="0.3" h="0.1"/> -->
      <!-- <cylinder_inirtia m="${mass}" r="${radius}" h="${width}" /> -->
      <inertia ixx="7.90866056" ixy="0.00000006" ixz="0" iyy="7.90866056" iyz="0" izz="2.48398783"/>
    </inertial>
  </link>
  <gazebo reference="$front_{name}_wheel">
    <material>Gazebo/White</material>
  </gazebo>
  <joint name="front_left_wheel_joint" type="revolute">
    <limit effort="100" lower="-0.9" upper="0.9" velocity="1"/>
    <origin rpy="1.5707963267948966 0 3.141592653589793" xyz="-0.061900000000000004 0.13175 0.077"/>
    <parent link="base_link"/>
    <child link="front_left_wheel"/>
    <axis xyz="0 1 0"/>
    <axis2 xyz="0 0 1"/>
  </joint>
  <link name="rear_right_wheel">
    <visual>
      <geometry>
        <cylinder length="0.003" radius="0.077"/>
      </geometry>
      <origin rpy="0 0 0" xyz="0 0 0"/>
      <material name="white"/>
    </visual>
    <collision>
      <origin rpy="0 0 0" xyz="0 0 0"/>
      <geometry>
        <cylinder length="0.003" radius="0.077"/>
      </geometry>
    </collision>
    <inertial>
      <origin rpy="0 0 0" xyz="0 0 0"/>
      <mass value="5.0"/>
      <!--<cylinder_inertia m="0.2" r="0.3" h="0.1"/> -->
      <!-- <cylinder_inirtia m="${mass}" r="${radius}" h="${width}" /> -->
      <inertia ixx="7.90866056" ixy="0.00000006" ixz="0" iyy="7.90866056" iyz="0" izz="2.48398783"/>
    </inertial>
  </link>
  <joint name="rear_right_wheel_joint" type="continuous">
    <origin rpy="1.5707963267948966 0 3.141592653589793" xyz="-0.5 -0.13175 0.077"/>
    <parent link="base_link"/>
    <child link="rear_right_wheel"/>
    <axis xyz="0 0 1"/>
  </joint>
  <link name="rear_left_wheel">
    <visual>
      <geometry>
        <cylinder length="0.003" radius="0.077"/>
      </geometry>
      <origin rpy="0 0 0" xyz="0 0 0"/>
      <material name="white"/>
    </visual>
    <collision>
      <origin rpy="0 0 0" xyz="0 0 0"/>
      <geometry>
        <cylinder length="0.003" radius="0.077"/>
      </geometry>
    </collision>
    <inertial>
      <origin rpy="0 0 0" xyz="0 0 0"/>
      <mass value="5.0"/>
      <!--<cylinder_inertia m="0.2" r="0.3" h="0.1"/> -->
      <!-- <cylinder_inirtia m="${mass}" r="${radius}" h="${width}" /> -->
      <inertia ixx="7.90866056" ixy="0.00000006" ixz="0" iyy="7.90866056" iyz="0" izz="2.48398783"/>
    </inertial>
  </link>
  <joint name="rear_left_wheel_joint" type="continuous">
    <origin rpy="1.5707963267948966 0 3.141592653589793" xyz="-0.5 0.13175 0.077"/>
    <parent link="base_link"/>
    <child link="rear_left_wheel"/>
    <axis xyz="0 0 1"/>
  </joint>
  <link name="camera_bottom_screw_frame">
    <visual>
      <geometry>
        <box size="0.02505 0.090 0.025"/>
      </geometry>
    </visual>
    <collision>
      <geometry>
        <box size="0.02505 0.090 0.025"/>
      </geometry>
    </collision>
  </link>
  <link name="camera_link"/>
  <link name="camera_depth_frame"/>
  <link name="camera_depth_optical_frame"/>
  <link name="camera_color_frame"/>
  <link name="camera_color_optical_frame"/>
  <link name="camera_left_ir_frame"/>
  <link name="camera_left_ir_optical_frame"/>
  <link name="camera_right_ir_frame"/>
  <link name="camera_right_ir_optical_frame"/>
  <joint name="camera_joint" type="fixed">
    <parent link="base_link"/>
    <child link="camera_bottom_screw_frame"/>
    <pose rpy="0 0 0" xyz="0.4 0 0.25"/>
  </joint>
  <joint name="camera_link_joint" type="fixed">
    <parent link="camera_bottom_screw_frame"/>
    <child link="camera_link"/>
    <pose rpy="0 0 0" xyz="0 0.0175 0.0125 "/>
  </joint>
  <joint name="camera_depth_joint" type="fixed">
    <parent link="camera_link"/>
    <child link="camera_depth_frame"/>
    <pose rpy="0 0 0" xyz="0 0 0"/>
  </joint>
  <joint name="camera_depth_optical_joint" type="fixed">
    <parent link="camera_depth_frame"/>
    <child link="camera_depth_optical_frame"/>
    <pose rpy="-1.57 0 -1.57" xyz="0 0 0 "/>
  </joint>
  <joint name="camera_color_joint" type="fixed">
    <parent link="camera_depth_frame"/>
    <child link="camera_color_frame"/>
    <pose rpy="0 0 0" xyz="0 0 0"/>
  </joint>
  <joint name="camera_color_optical_joint" type="fixed">
    <parent link="camera_color_frame"/>
    <child link="camera_color_optical_frame"/>
    <pose rpy="-1.57 0 -1.57" xyz="0 0 0 "/>
  </joint>
  <joint name="camera_left_ir_joint" type="fixed">
    <parent link="camera_depth_frame"/>
    <child link="camera_left_ir_frame"/>
    <pose rpy="0 0 0 " xyz="0 0 0 "/>
  </joint>
  <joint name="camera_left_ir_optical_joint" type="fixed">
    <parent link="camera_left_ir_frame"/>
    <child link="camera_left_ir_optical_frame"/>
    <pose rpy="-1.57 0 -1.57" xyz="0 0 0 "/>
  </joint>
  <joint name="camera_right_ir_joint" type="fixed">
    <parent link="camera_depth_frame"/>
    <child link="camera_right_ir_frame"/>
    <pose rpy="0 0 0" xyz="0 -0.050 0 "/>
  </joint>
  <joint name="camera_right_ir_optical_joint" type="fixed">
    <parent link="camera_right_ir_frame"/>
    <child link="camera_right_ir_optical_frame"/>
    <pose rpy="-1.57 0 -1.57" xyz="0 0 0 "/>
  </joint>
  <link name="human_link">
    <visual>
      <geometry>
        <box size="0.3 0.2 0.1"/>
      </geometry>
      <material name="blue"/>
    </visual>
  </link>
  <joint name="base_to_human" type="fixed">
    <origin rpy="0 1.5707963267948966 0" xyz="-0.5 0.0 0.2"/>
    <parent link="base_link"/>
    <child link="human_link"/>
  </joint>
</robot>
